[{"user_id": 14057, "stars": [], "topic_id": 19627, "date_created": 1302876479.981441, "message": "i got this problem randomly too", "group_id": 88, "id": 700446}, {"user_id": 10087, "stars": [], "topic_id": 19627, "date_created": 1302876398.627589, "message": "working again", "group_id": 88, "id": 700440}, {"user_id": 9907, "stars": [], "topic_id": 19627, "date_created": 1302876601.953496, "message": "Database.connect(**conn_params)\n[...]\nOperationalError: asynchronous connection failed\n\nlooks like the database was restarted", "group_id": 88, "id": 700460}, {"user_id": 10087, "stars": [], "topic_id": 19627, "date_created": 1302876183.5304339, "message": "This is what I got and am still getting when trying to access convore on chromium. but it works ok for me in firefox now", "group_id": 88, "id": 700422}, {"user_id": 10087, "stars": [], "topic_id": 19627, "date_created": 1302876150.0273011, "message": "Traceback (most recent call last):\n  File \"/home/convore/virtualenvs/convore/lib/python2.6/site-packages/eventlet/wsgi.py\", line 336, in handle_one_response\n    result = self.application(self.environ, start_response)\n  File \"/home/convore/virtualenvs/convore/lib/python2.6/site-packages/django/core/handlers/wsgi.py\", line 245, in __call__\n    response = middleware_method(request, response)\n  File \"/home/convore/convore/django_ext/middleware/log.py\", line 30, in process_response\n    'trk': getattr(request, 'trk', None),\n  File \"/home/convore/convore/django_ext/logging.py\", line 27, in log_event\n    if has_session and request.user.is_authenticated():\n  File \"/home/convore/virtualenvs/convore/lib/python2.6/site-packages/django/contrib/auth/middleware.py\", line 9, in __get__\n    request._cached_user = get_user(request)\n  File \"/home/convore/virtualenvs/convore/lib/python2.6/site-packages/django/contrib/auth/__init__.py\", line 102, in get_user\n    user = backend.get_user(user_id) or AnonymousUser()\n  File \"/home/convore/convore/django_ext/authentication_backends.py\", line 9, in get_user\n    return User.objects.select_related('profile').get(pk=user_id)\n  File \"/home/convore/virtualenvs/convore/lib/python2.6/site-packages/django/db/models/query.py\", line 342, in get\n    num = len(clone)\n  File \"/home/convore/virtualenvs/convore/lib/python2.6/site-packages/django/db/models/query.py\", line 80, in __len__\n    self._result_cache = list(self.iterator())\n  File \"/home/convore/virtualenvs/convore/lib/python2.6/site-packages/django/db/models/query.py\", line 271, in iterator\n    for row in compiler.results_iter():\n  File \"/home/convore/virtualenvs/convore/lib/python2.6/site-packages/django/db/models/sql/compiler.py\", line 677, in results_iter\n    for rows in self.execute_sql(MULTI):\n  File \"/home/convore/virtualenvs/convore/lib/python2.6/site-packages/django/db/models/sql/compiler.py\", line 731, in execute_sql\n    cursor = self.connection.cursor()\n  File \"/home/convore/virtualenvs/convore/lib/python2.6/site-packages/django/db/backends/__init__.py\", line 75, in cursor\n    cursor = self._cursor()\n  File \"/home/convore/virtualenvs/convore/lib/python2.6/site-packages/django/db/backends/postgresql_psycopg2/base.py\", line 136, in _cursor\n    self.connection = Database.connect(**conn_params)\n  File \"/home/convore/virtualenvs/convore/lib/python2.6/site-packages/eventlet/support/psycopg2_patcher.py\", line 44, in eventlet_wait_callback\n    state = conn.poll()\nOperationalError: asynchronous connection failed", "group_id": 88, "id": 700420}, {"user_id": 1, "stars": [], "topic_id": 19627, "date_created": 1302884243.261404, "message": "Sorry about this guys, we scrambled to fix it and we're going to root cause the issue and figure out how we can stop it from happening again", "group_id": 88, "id": 702033}, {"user_id": 8119, "stars": [], "topic_id": 19627, "date_created": 1313740859.927515, "message": "Given this is the #2 Google result for this topic, can you share what you did to fix it?", "group_id": 88, "id": 1908586}, {"user_id": 25337, "stars": [], "topic_id": 19627, "date_created": 1321375498.7370689, "message": "Yep - I'd be interested in knowing what the root cause was here too (assuming it's not very Convore-specific, of course)", "group_id": 88, "id": 2578740}, {"user_id": 2362, "stars": [], "topic_id": 19627, "date_created": 1322507262.196867, "message": "Would be interesting in hearing this as well.", "group_id": 88, "id": 2660076}]