[{"user_id": 7691, "stars": [], "topic_id": 44477, "date_created": 1314317969.294205, "message": "Getting random \"ValueError: Invalid parameter string\" being triggered by line 285 from the oauth2 library's `__init__.py` file. Any ideas?", "group_id": 5196, "id": 1963391}, {"user_id": 20656, "stars": [], "topic_id": 44477, "date_created": 1314319892.6372011, "message": "@kennethlove, I've got this one and fixed it a few days ago, so using git version should work, also I've just tagged v0.5.7 and uploaded it to pypi.", "group_id": 5196, "id": 1963563}, {"user_id": 7691, "stars": [], "topic_id": 44477, "date_created": 1314323953.997149, "message": "Thanks. Dev partner tested 0.5.7 and confirmed it fixed the issue for us.", "group_id": 5196, "id": 1964139}]