[{"user_id": 36639, "stars": [], "topic_id": 40743, "date_created": 1309372071.2281101, "message": "I'm not sure I see how SOCIAL_AUTH_NEW_USER_REDIRECT_URL get used. It seems to me that when complete_process() gets called, the default redirect url from the LOGIN_REDIRECT_URL setting was already added when auth_process() or associate() was called earlier. I am also seeing this at runtime: If I social-login under a non-existing user and without next query string value set, after auth it redirects to LOGIN_REDIRECT_URL instead of NEW_USER_REDIRECT_URL. Please clarify. Thanks.", "group_id": 5196, "id": 1519699}, {"user_id": 20656, "stars": [], "topic_id": 40743, "date_created": 1309373239.6227541, "message": "Silly question, do you have SOCIAL_AUTH_NEW_USER_REDIRECT_URL defined in your settings?", "group_id": 5196, "id": 1519973}, {"user_id": 36639, "stars": [], "topic_id": 40743, "date_created": 1309374860.4208109, "message": "Yes, and my computer is plugged in to the power.... The LOGIN_REDIRECT_URL is getting used instead, and they are defined on consecutive lines in my settings file.", "group_id": 5196, "id": 1520380}, {"user_id": 36639, "stars": [], "topic_id": 40743, "date_created": 1309380626.872782, "message": "Can you please explain to me how the complete_process() method will ever set the redirect url to NEW_USER_REDIRECT, if the REDIRECT_FIELD_NAME value was already set earlier in auth_process to LOGIN_REDIRECT_URL? Thank you.", "group_id": 5196, "id": 1521889}, {"user_id": 36639, "stars": [], "topic_id": 40743, "date_created": 1309380815.573411, "message": "Let me suggest what the code in complete_process() should look like:\n\n        url = request.session.pop(REDIRECT_FIELD_NAME, '')\n        if NEW_USER_REDIRECT and getattr(user, 'is_new', False):\n            url = NEW_USER_REDIRECT\n        elif not url:\n            url = DEFAULT_REDIRECT", "group_id": 5196, "id": 1521958}, {"user_id": 20831, "stars": [], "topic_id": 40743, "date_created": 1309701975.5407159, "message": "@jacobg created a new issue on Github with this https://github.com/omab/django-social-auth/issues/98", "group_id": 5196, "id": 1552149}, {"user_id": 20831, "stars": [], "topic_id": 40743, "date_created": 1309701724.10901, "message": "Hey @jacbog, I've been having the same issue, but your suggested snippet for complete_process seems to do the trick.", "group_id": 5196, "id": 1552127}, {"user_id": 20656, "stars": [], "topic_id": 40743, "date_created": 1309722187.6254621, "message": "A fix was pushed to master a few minutes ago, thanks everybody.", "group_id": 5196, "id": 1553682}]