[{"user_id": 44583, "stars": [], "topic_id": 48942, "date_created": 1325003012.667825, "message": "the correct setting is 'socialauth_complete' but readthedocs.org has the incorrect value  http://django-social-auth.readthedocs.org/en/latest/configuration.html", "group_id": 5196, "id": 2747491}, {"user_id": 44583, "stars": [], "topic_id": 48942, "date_created": 1325003118.8700769, "message": "and for some reason the master branch in github also has the incorrect value https://github.com/omab/django-social-auth/blob/master/doc/configuration.rst   but  the pypi site has the correct value:  http://pypi.python.org/pypi/django-social-auth/", "group_id": 5196, "id": 2747493}, {"user_id": 44583, "stars": [], "topic_id": 48942, "date_created": 1325003544.2555189, "message": "if you have the incorrect value, you will see this error message: Reverse for 'complete' with arguments '(u'facebook',)' and keyword arguments '{}' not found.", "group_id": 5196, "id": 2747494}, {"user_id": 20656, "stars": [], "topic_id": 48942, "date_created": 1325003754.7887521, "message": "Fixed: https://github.com/omab/django-social-auth/commit/a854c8bad4f465d48bb3e3499b58ff339a61f058", "group_id": 5196, "id": 2747496}, {"user_id": 44583, "stars": [], "topic_id": 48942, "date_created": 1325006310.000737, "message": "wow!  fixed 4 minutes after the bug is reported --  omab is super-responsive!!  Thanks!!", "group_id": 5196, "id": 2747499}]